Workbook

Sheet SPOS
A1: NO | B1: NO ENTRI | C1: NOPOL | D1: NAMA / ALAMAT | E1: DESA | F1: KECAMATAN | G1: POTENSI | H1: TGCETAK | I1: KET | J1: ID_Login | K1: Password
A2: 1 | B2: 2603076537 | C2: S 4629 OBU | D2: WESTI ERLIFIANINGRUM | E2: DS BRAMBANG | F2: DIWEK | G2: 243200 | H2: 46091 | J2: =IF(E2="", "", IFERROR(VLOOKUP(IFERROR(VLOOKUP(SUBSTITUTE(E2,"DS ","")&F2, wilayahfix!$A:$D, 2, 0), ""), user!$B:$D, 2, 0), "TIDAK KETEMU")) -> 120201219820720072991 | K2: =IF(E2="", "", IFERROR(VLOOKUP(IFERROR(VLOOKUP(SUBSTITUTE(E2,"DS ","")&F2, wilayahfix!$A:$D, 2, 0), ""), user!$B:$D, 3, 0), "")) -> KADIR
D3: DSN LEGARANG
A4: 2 | B4: 2603064038 | C4: S 3989 ON | D4: DENI ANDRIANTO | E4: DS KAYANGAN | F4: DIWEK | G4: 209200 | H4: 46091 | J4: =IF(E4="", "", IFERROR(VLOOKUP(IFERROR(VLOOKUP(SUBSTITUTE(E4,"DS ","")&F4, wilayahfix!$A:$D, 2, 0), ""), user!$B:$D, 2, 0), "TIDAK KETEMU")) -> 120201219820720072991 | K4: =IF(E4="", "", IFERROR(VLOOKUP(IFERROR(VLOOKUP(SUBSTITUTE(E4,"DS ","")&F4, wilayahfix!$A:$D, 2, 0), ""), user!$B:$D, 3, 0), "")) -> KADIR
D5: DSN TEBON
A6: 3 | B6: 2603071699 | C6: S 2636 OBF | D6: SUYATI | E6: DS NGUDIREJO | F6: DIWEK | G6: 151900 | H6: 46091 | J6: =IF(E6="", "", IFERROR(VLOOKUP(IFERROR(VLOOKUP(SUBSTITUTE(E6,"DS ","")&F6, wilayahfix!$A:$D, 2, 0), ""), user!$B:$D, 2, 0), "TIDAK KETEMU")) -> 120291019860720072992 | K6: =IF(E6="", "", IFERROR(VLOOKUP(IFERROR(VLOOKUP(SUBSTITUTE(E6,"DS ","")&F6, wilayahfix!$A:$D, 2, 0), ""), user!$B:$D, 3, 0), "")) -> SIAPP
D7: DSN GEDANGAN
A8: 4 | B8: 2603099049 | C8: S 2422 OBF | D8: ARYO PUTRO | E8: DS BUGASUR KDLMN | F8: GUDO | G8: 181800 | H8: 46091 | J8: =IF(E8="", "", IFERROR(VLOOKUP(IFERROR(VLOOKUP(SUBSTITUTE(E8,"DS ","")&F8, wilayahfix!$A:$D, 2, 0), ""), user!$B:$D, 2, 0), "TIDAK KETEMU")) -> 198311252010011005 | K8: =IF(E8="", "", IFERROR(VLOOKUP(IFERROR(VLOOKUP(SUBSTITUTE(E8,"DS ","")&F8, wilayahfix!$A:$D, 2, 0), ""), user!$B:$D, 3, 0), "")) -> YAFET
D9: DUSUN SUMBERMIRI
A10: 5 | B10: 2603082823 | C10: S 6944 OAL | D10: IMROATUL FARIDA | E10: DS TANGGUNGAN | F10: GUDO | G10: 196800 | H10: 46091 | J10: =IF(E10="", "", IFERROR(VLOOKUP(IFERROR(VLOOKUP(SUBSTITUTE(E10,"DS ","")&F10, wilayahfix!$A:$D, 2, 0), ""), user!$B:$D, 2, 0), "TIDAK KETEMU")) -> 198311252010011005 | K10: =IF(E10="", "", IFERROR(VLOOKUP(IFERROR(VLOOKUP(SUBSTITUTE(E10,"DS ","")&F10, wilayahfix!$A:$D, 2, 0), ""), user!$B:$D, 3, 0), "")) -> YAFET
D11: DS TANGGUNGAN RW 02/06
A12: 6 | B12: 2603096239 | C12: S 4998 OCU | D12: MUHAMMAD FAQIN RIZAL AZZALI | E12: DS BADANG | F12: NGORO | G12: 267300 | H12: 46091 | J12: =IF(E12="", "", IFERROR(VLOOKUP(IFERROR(VLOOKUP(SUBSTITUTE(E12,"DS ","")&F12, wilayahfix!$A:$D, 2, 0), ""), user!$B:$D, 2, 0), "TIDAK KETEMU")) -> 120281219860120113003 | K12: =IF(E12="", "", IFERROR(VLOOKUP(IFERROR(VLOOKUP(SUBSTITUTE(E12,"DS ","")&F12, wilayahfix!$A:$D, 2, 0), ""), user!$B:$D, 3, 0), "")) -> 250005
D13: DSN SUKOTI
A14: 7 | B14: 2603076608 | C14: S 3922 OAJ | D14: UNTUNG | E14: DS BADANG | F14: NGORO | G14: 196800 | H14: 46091 | J14: =IF(E14="", "", IFERROR(VLOOKUP(IFERROR(VLOOKUP(SUBSTITUTE(E14,"DS ","")&F14, wilayahfix!$A:$D, 2, 0), ""), user!$B:$D, 2, 0), "TIDAK KETEMU")) -> 120281219860120113003 | K14: =IF(E14="", "", IFERROR(VLOOKUP(IFERROR(VLOOKUP(SUBSTITUTE(E14,"DS ","")&F14, wilayahfix!$A:$D, 2, 0), ""), user!$B:$D, 3, 0), "")) -> 250005
D15: WONOASRI
A16: 8 | B16: 2603075042 | C16: S 2362 OBF | D16: FEBRIANA DWI EVAYANTI | E16: DS KAUMAN | F16: NGORO | G16: 270600 | H16: 46091 | J16: =IF(E16="", "", IFERROR(VLOOKUP(IFERROR(VLOOKUP(SUBSTITUTE(E16,"DS ","")&F16, wilayahfix!$A:$D, 2, 0), ""), user!$B:$D, 2, 0), "TIDAK KETEMU")) -> 120281219860120113003 | K16: =IF(E16="", "", IFERROR(VLOOKUP(IFERROR(VLOOKUP(SUBSTITUTE(E16,"DS ","")&F16, wilayahfix!$A:$D, 2, 0), ""), user!$B:$D, 3, 0), "")) -> 250005
D17: DSN KAUMAN
A18: 9 | B18: 2603083988 | C18: S 3983 ON | D18: FARIDA FITRIANA | E18: DS KAUMAN | F18: NGORO | G18: 216700 | H18: 46091 | J18: =IF(E18="", "", IFERROR(VLOOKUP(IFERROR(VLOOKUP(SUBSTITUTE(E18,"DS ","")&F18, wilayahfix!$A:$D, 2, 0), ""), user!$B:$D, 2, 0), "TIDAK KETEMU")) -> 120281219860120113003 | K18: =IF(E18="", "", IFERROR(VLOOKUP(IFERROR(VLOOKUP(SUBSTITUTE(E18,"DS ","")&F18, wilayahfix!$A:$D, 2, 0), ""), user!$B:$D, 3, 0), "")) -> 250005
D19: DSN KRENGGAN
A20: 10 | B20: 2603028068 | C20: S 6901 OCH | D20: ALIEFFIAN SETYO R | E20: DS NGORO | F20: NGORO | G20: 198400 | H20: 46091 | J20: =IF(E20="", "", IFERROR(VLOOKUP(IFERROR(VLOOKUP(SUBSTITUTE(E20,"DS ","")&F20, wilayahfix!$A:$D, 2, 0), ""), user!$B:$D, 2, 0), "TIDAK KETEMU")) -> 120281219860120113003 | K20: =IF(E20="", "", IFERROR(VLOOKUP(IFERROR(VLOOKUP(SUBSTITUTE(E20,"DS ","")&F20, wilayahfix!$A:$D, 2, 0), ""), user!$B:$D, 3, 0), "")) -> 250005
D21: JL SALAK 4
A22: 11 | B22: 2603012223 | C22: S 3972 ON | D22: NURLAILI | E22: DS NGORO | F22: NGORO | G22: 198400 | H22: 46091 | J22: =IF(E22="", "", IFERROR(VLOOKUP(IFERROR(VLOOKUP(SUBSTITUTE(E22,"DS ","")&F22, wilayahfix!$A:$D, 2, 0), ""), user!$B:$D, 2, 0), "TIDAK KETEMU")) -> 120281219860120113003 | K22: =IF(E22="", "", IFERROR(VLOOKUP(IFERROR(VLOOKUP(SUBSTITUTE(E22,"DS ","")&F22, wilayahfix!$A:$D, 2, 0), ""), user!$B:$D, 3, 0), "")) -> 250005
D23: JL SALAK
A24: 12 | B24: 2603087991 | C24: S 4670 OBU | D24: SRI WAHYUNI | E24: DS NGORO | F24: NGORO | G24: 183500 | H24: 46091 | J24: =IF(E24="", "", IFERROR(VLOOKUP(IFERROR(VLOOKUP(SUBSTITUTE(E24,"DS ","")&F24, wilayahfix!$A:$D, 2, 0), ""), user!$B:$D, 2, 0), "TIDAK KETEMU")) -> 120281219860120113003 | K24: =IF(E24="", "", IFERROR(VLOOKUP(IFERROR(VLOOKUP(SUBSTITUTE(E24,"DS ","")&F24, wilayahfix!$A:$D, 2, 0), ""), user!$B:$D, 3, 0), "")) -> 250005
D25: JL SEDAP MALAM
A26: 13 | B26: 2603078723 | C26: S 4984 OCU | D26: SIGIT PANCORO | E26: DS PULOREJO | F26: NGORO | G26: 417500 | H26: 46091 | J26: =IF(E26="", "", IFERROR(VLOOKUP(IFERROR(VLOOKUP(SUBSTITUTE(E26,"DS ","")&F26, wilayahfix!$A:$D, 2, 0), ""), user!$B:$D, 2, 0), "TIDAK KETEMU")) -> 120281219860120113003 | K26: =IF(E26="", "", IFERROR(VLOOKUP(IFERROR(VLOOKUP(SUBSTITUTE(E26,"DS ","")&F26, wilayahfix!$A:$D, 2, 0), ""), user!$B:$D, 3, 0), "")) -> 250005
D27: DSN. PULOREJO
J28: =IF(E28="", "", IFERROR(VLOOKUP(IFERROR(VLOOKUP(SUBSTITUTE(E28,"DS ","")&F28, wilayahfix!$A:$D, 2, 0), ""), user!$B:$D, 2, 0), "TIDAK KETEMU")) | K28: =IF(E28="", "", IFERROR(VLOOKUP(IFERROR(VLOOKUP(SUBSTITUTE(E28,"DS ","")&F28, wilayahfix!$A:$D, 2, 0), ""), user!$B:$D, 3, 0), ""))
J30: =IF(E30="", "", IFERROR(VLOOKUP(IFERROR(VLOOKUP(SUBSTITUTE(E30,"DS ","")&F30, wilayahfix!$A:$D, 2, 0), ""), user!$B:$D, 2, 0), "TIDAK KETEMU")) | K30: =IF(E30="", "", IFERROR(VLOOKUP(IFERROR(VLOOKUP(SUBSTITUTE(E30,"DS ","")&F30, wilayahfix!$A:$D, 2, 0), ""), user!$B:$D, 3, 0), ""))
J32: =IF(E32="", "", IFERROR(VLOOKUP(IFERROR(VLOOKUP(SUBSTITUTE(E32,"DS ","")&F32, wilayahfix!$A:$D, 2, 0), ""), user!$B:$D, 2, 0), "TIDAK KETEMU")) | K32: =IF(E32="", "", IFERROR(VLOOKUP(IFERROR(VLOOKUP(SUBSTITUTE(E32,"DS ","")&F32, wilayahfix!$A:$D, 2, 0), ""), user!$B:$D, 3, 0), ""))
J34: =IF(E34="", "", IFERROR(VLOOKUP(IFERROR(VLOOKUP(SUBSTITUTE(E34,"DS ","")&F34, wilayahfix!$A:$D, 2, 0), ""), user!$B:$D, 2, 0), "TIDAK KETEMU")) | K34: =IF(E34="", "", IFERROR(VLOOKUP(IFERROR(VLOOKUP(SUBSTITUTE(E34,"DS ","")&F34, wilayahfix!$A:$D, 2, 0), ""), user!$B:$D, 3, 0), ""))
J36: =IF(E36="", "", IFERROR(VLOOKUP(IFERROR(VLOOKUP(SUBSTITUTE(E36,"DS ","")&F36, wilayahfix!$A:$D, 2, 0), ""), user!$B:$D, 2, 0), "TIDAK KETEMU")) | K36: =IF(E36="", "", IFERROR(VLOOKUP(IFERROR(VLOOKUP(SUBSTITUTE(E36,"DS ","")&F36, wilayahfix!$A:$D, 2, 0), ""), user!$B:$D, 3, 0), ""))
J38: =IF(E38="", "", IFERROR(VLOOKUP(IFERROR(VLOOKUP(SUBSTITUTE(E38,"DS ","")&F38, wilayahfix!$A:$D, 2, 0), ""), user!$B:$D, 2, 0), "TIDAK KETEMU")) | K38: =IF(E38="", "", IFERROR(VLOOKUP(IFERROR(VLOOKUP(SUBSTITUTE(E38,"DS ","")&F38, wilayahfix!$A:$D, 2, 0), ""), user!$B:$D, 3, 0), ""))
J40: =IF(E40="", "", IFERROR(VLOOKUP(IFERROR(VLOOKUP(SUBSTITUTE(E40,"DS ","")&F40, wilayahfix!$A:$D, 2, 0), ""), user!$B:$D, 2, 0), "TIDAK KETEMU")) | K40: =IF(E40="", "", IFERROR(VLOOKUP(IFERROR(VLOOKUP(SUBSTITUTE(E40,"DS ","")&F40, wilayahfix!$A:$D, 2, 0), ""), user!$B:$D, 3, 0), ""))
J42: =IF(E42="", "", IFERROR(VLOOKUP(IFERROR(VLOOKUP(SUBSTITUTE(E42,"DS ","")&F42, wilayahfix!$A:$D, 2, 0), ""), user!$B:$D, 2, 0), "TIDAK KETEMU")) | K42: =IF(E42="", "", IFERROR(VLOOKUP(IFERROR(VLOOKUP(SUBSTITUTE(E42,"DS ","")&F42, wilayahfix!$A:$D, 2, 0), ""), user!$B:$D, 3, 0), ""))
J44: =IF(E44="", "", IFERROR(VLOOKUP(IFERROR(VLOOKUP(SUBSTITUTE(E44,"DS ","")&F44, wilayahfix!$A:$D, 2, 0), ""), user!$B:$D, 2, 0), "TIDAK KETEMU")) | K44: =IF(E44="", "", IFERROR(VLOOKUP(IFERROR(VLOOKUP(SUBSTITUTE(E44,"DS ","")&F44, wilayahfix!$A:$D, 2, 0), ""), user!$B:$D, 3, 0), ""))
J46: =IF(E46="", "", IFERROR(VLOOKUP(IFERROR(VLOOKUP(SUBSTITUTE(E46,"DS ","")&F46, wilayahfix!$A:$D, 2, 0), ""), user!$B:$D, 2, 0), "TIDAK KETEMU")) | K46: =IF(E46="", "", IFERROR(VLOOKUP(IFERROR(VLOOKUP(SUBSTITUTE(E46,"DS ","")&F46, wilayahfix!$A:$D, 2, 0), ""), user!$B:$D, 3, 0), ""))
J48: =IF(E48="", "", IFERROR(VLOOKUP(IFERROR(VLOOKUP(SUBSTITUTE(E48,"DS ","")&F48, wilayahfix!$A:$D, 2, 0), ""), user!$B:$D, 2, 0), "TIDAK KETEMU")) | K48: =IF(E48="", "", IFERROR(VLOOKUP(IFERROR(VLOOKUP(SUBSTITUTE(E48,"DS ","")&F48, wilayahfix!$A:$D, 2, 0), ""), user!$B:$D, 3, 0), ""))
J50: =IF(E50="", "", IFERROR(VLOOKUP(IFERROR(VLOOKUP(SUBSTITUTE(E50,"DS ","")&F50, wilayahfix!$A:$D, 2, 0), ""), user!$B:$D, 2, 0), "TIDAK KETEMU")) | K50: =IF(E50="", "", IFERROR(VLOOKUP(IFERROR(VLOOKUP(SUBSTITUTE(E50,"DS ","")&F50, wilayahfix!$A:$D, 2, 0), ""), user!$B:$D, 3, 0), ""))
... J198: =IF(E198="", "", IFERROR(VLOOKUP(IFERROR(VLOOKUP(SUBSTITUTE(E198,"DS ","")&F198, wilayahfix!$A:$D, 2, 0), ""), user!$B:$D, 2, 0), "TIDAK KETEMU")) | K198: =IF(E198="", "", IFERROR(VLOOKUP(IFERROR(VLOOKUP(SUBSTITUTE(E198,"DS ","")&F198, wilayahfix!$A:$D, 2, 0), ""), user!$B:$D, 3, 0), ""))
...

Sheet NPP
A1: NO | B1: NO ENTRI | C1: NOPOL | D1: NAMA / ALAMAT | E1: DESA | F1: KECAMATAN | G1: POTENSI | H1: TGCETAK | I1: KET | J1: ID_Login | K1: Password
A2: 1 | B2: 2603076537 | C2: S 4629 OBU | D2: WESTI ERLIFIANINGRUM | E2: DS BRAMBANG | F2: DIWEK | G2: 243200 | H2: 46091 | J2: =IF(E2="", "", IFERROR(VLOOKUP(IFERROR(VLOOKUP(SUBSTITUTE(E2,"DS ","")&F2, wilayahfix!$A:$D, 2, 0), ""), user!$B:$D, 2, 0), "TIDAK KETEMU")) -> 120201219820720072991 | K2: =IF(E2="", "", IFERROR(VLOOKUP(IFERROR(VLOOKUP(SUBSTITUTE(E2,"DS ","")&F2, wilayahfix!$A:$D, 2, 0), ""), user!$B:$D, 3, 0), "")) -> KADIR
D3: DSN LEGARANG
A4: 2 | B4: 2603064038 | C4: S 3989 ON | D4: DENI ANDRIANTO | E4: DS KAYANGAN | F4: DIWEK | G4: 209200 | H4: 46091 | J4: =IF(E4="", "", IFERROR(VLOOKUP(IFERROR(VLOOKUP(SUBSTITUTE(E4,"DS ","")&F4, wilayahfix!$A:$D, 2, 0), ""), user!$B:$D, 2, 0), "TIDAK KETEMU")) -> 120201219820720072991 | K4: =IF(E4="", "", IFERROR(VLOOKUP(IFERROR(VLOOKUP(SUBSTITUTE(E4,"DS ","")&F4, wilayahfix!$A:$D, 2, 0), ""), user!$B:$D, 3, 0), "")) -> KADIR
D5: DSN TEBON
A6: 3 | B6: 2603071699 | C6: S 2636 OBF | D6: SUYATI | E6: DS NGUDIREJO | F6: DIWEK | G6: 151900 | H6: 46091 | J6: =IF(E6="", "", IFERROR(VLOOKUP(IFERROR(VLOOKUP(SUBSTITUTE(E6,"DS ","")&F6, wilayahfix!$A:$D, 2, 0), ""), user!$B:$D, 2, 0), "TIDAK KETEMU")) -> 120291019860720072992 | K6: =IF(E6="", "", IFERROR(VLOOKUP(IFERROR(VLOOKUP(SUBSTITUTE(E6,"DS ","")&F6, wilayahfix!$A:$D, 2, 0), ""), user!$B:$D, 3, 0), "")) -> SIAPP
D7: DSN GEDANGAN
A8: 4 | B8: 2603099049 | C8: S 2422 OBF | D8: ARYO PUTRO | E8: DS BUGASUR KDLMN | F8: GUDO | G8: 181800 | H8: 46091 | J8: =IF(E8="", "", IFERROR(VLOOKUP(IFERROR(VLOOKUP(SUBSTITUTE(E8,"DS ","")&F8, wilayahfix!$A:$D, 2, 0), ""), user!$B:$D, 2, 0), "TIDAK KETEMU")) -> 198311252010011005 | K8: =IF(E8="", "", IFERROR(VLOOKUP(IFERROR(VLOOKUP(SUBSTITUTE(E8,"DS ","")&F8, wilayahfix!$A:$D, 2, 0), ""), user!$B:$D, 3, 0), "")) -> YAFET
D9: DUSUN SUMBERMIRI
A10: 5 | B10: 2603082823 | C10: S 6944 OAL | D10: IMROATUL FARIDA | E10: DS TANGGUNGAN | F10: GUDO | G10: 196800 | H10: 46091 | J10: =IF(E10="", "", IFERROR(VLOOKUP(IFERROR(VLOOKUP(SUBSTITUTE(E10,"DS ","")&F10, wilayahfix!$A:$D, 2, 0), ""), user!$B:$D, 2, 0), "TIDAK KETEMU")) -> 198311252010011005 | K10: =IF(E10="", "", IFERROR(VLOOKUP(IFERROR(VLOOKUP(SUBSTITUTE(E10,"DS ","")&F10, wilayahfix!$A:$D, 2, 0), ""), user!$B:$D, 3, 0), "")) -> YAFET
D11: DS TANGGUNGAN RW 02/06
A12: 6 | B12: 2603096239 | C12: S 4998 OCU | D12: MUHAMMAD FAQIN RIZAL AZZALI | E12: DS BADANG | F12: NGORO | G12: 267300 | H12: 46091 | J12: =IF(E12="", "", IFERROR(VLOOKUP(IFERROR(VLOOKUP(SUBSTITUTE(E12,"DS ","")&F12, wilayahfix!$A:$D, 2, 0), ""), user!$B:$D, 2, 0), "TIDAK KETEMU")) -> 120281219860120113003 | K12: =IF(E12="", "", IFERROR(VLOOKUP(IFERROR(VLOOKUP(SUBSTITUTE(E12,"DS ","")&F12, wilayahfix!$A:$D, 2, 0), ""), user!$B:$D, 3, 0), "")) -> 250005
D13: DSN SUKOTI
A14: 7 | B14: 2603076608 | C14: S 3922 OAJ | D14: UNTUNG | E14: DS BADANG | F14: NGORO | G14: 196800 | H14: 46091 | J14: =IF(E14="", "", IFERROR(VLOOKUP(IFERROR(VLOOKUP(SUBSTITUTE(E14,"DS ","")&F14, wilayahfix!$A:$D, 2, 0), ""), user!$B:$D, 2, 0), "TIDAK KETEMU")) -> 120281219860120113003 | K14: =IF(E14="", "", IFERROR(VLOOKUP(IFERROR(VLOOKUP(SUBSTITUTE(E14,"DS ","")&F14, wilayahfix!$A:$D, 2, 0), ""), user!$B:$D, 3, 0), "")) -> 250005
D15: WONOASRI
A16: 8 | B16: 2603075042 | C16: S 2362 OBF | D16: FEBRIANA DWI EVAYANTI | E16: DS KAUMAN | F16: NGORO | G16: 270600 | H16: 46091 | J16: =IF(E16="", "", IFERROR(VLOOKUP(IFERROR(VLOOKUP(SUBSTITUTE(E16,"DS ","")&F16, wilayahfix!$A:$D, 2, 0), ""), user!$B:$D, 2, 0), "TIDAK KETEMU")) -> 120281219860120113003 | K16: =IF(E16="", "", IFERROR(VLOOKUP(IFERROR(VLOOKUP(SUBSTITUTE(E16,"DS ","")&F16, wilayahfix!$A:$D, 2, 0), ""), user!$B:$D, 3, 0), "")) -> 250005
D17: DSN KAUMAN
A18: 9 | B18: 2603083988 | C18: S 3983 ON | D18: FARIDA FITRIANA | E18: DS KAUMAN | F18: NGORO | G18: 216700 | H18: 46091 | J18: =IF(E18="", "", IFERROR(VLOOKUP(IFERROR(VLOOKUP(SUBSTITUTE(E18,"DS ","")&F18, wilayahfix!$A:$D, 2, 0), ""), user!$B:$D, 2, 0), "TIDAK KETEMU")) -> 120281219860120113003 | K18: =IF(E18="", "", IFERROR(VLOOKUP(IFERROR(VLOOKUP(SUBSTITUTE(E18,"DS ","")&F18, wilayahfix!$A:$D, 2, 0), ""), user!$B:$D, 3, 0), "")) -> 250005
D19: DSN KRENGGAN
A20: 10 | B20: 2603028068 | C20: S 6901 OCH | D20: ALIEFFIAN SETYO R | E20: DS NGORO | F20: NGORO | G20: 198400 | H20: 46091 | J20: =IF(E20="", "", IFERROR(VLOOKUP(IFERROR(VLOOKUP(SUBSTITUTE(E20,"DS ","")&F20, wilayahfix!$A:$D, 2, 0), ""), user!$B:$D, 2, 0), "TIDAK KETEMU")) -> 120281219860120113003 | K20: =IF(E20="", "", IFERROR(VLOOKUP(IFERROR(VLOOKUP(SUBSTITUTE(E20,"DS ","")&F20, wilayahfix!$A:$D, 2, 0), ""), user!$B:$D, 3, 0), "")) -> 250005
D21: JL SALAK 4
A22: 11 | B22: 2603012223 | C22: S 3972 ON | D22: NURLAILI | E22: DS NGORO | F22: NGORO | G22: 198400 | H22: 46091 | J22: =IF(E22="", "", IFERROR(VLOOKUP(IFERROR(VLOOKUP(SUBSTITUTE(E22,"DS ","")&F22, wilayahfix!$A:$D, 2, 0), ""), user!$B:$D, 2, 0), "TIDAK KETEMU")) -> 120281219860120113003 | K22: =IF(E22="", "", IFERROR(VLOOKUP(IFERROR(VLOOKUP(SUBSTITUTE(E22,"DS ","")&F22, wilayahfix!$A:$D, 2, 0), ""), user!$B:$D, 3, 0), "")) -> 250005
D23: JL SALAK
A24: 12 | B24: 2603087991 | C24: S 4670 OBU | D24: SRI WAHYUNI | E24: DS NGORO | F24: NGORO | G24: 183500 | H24: 46091 | J24: =IF(E24="", "", IFERROR(VLOOKUP(IFERROR(VLOOKUP(SUBSTITUTE(E24,"DS ","")&F24, wilayahfix!$A:$D, 2, 0), ""), user!$B:$D, 2, 0), "TIDAK KETEMU")) -> 120281219860120113003 | K24: =IF(E24="", "", IFERROR(VLOOKUP(IFERROR(VLOOKUP(SUBSTITUTE(E24,"DS ","")&F24, wilayahfix!$A:$D, 2, 0), ""), user!$B:$D, 3, 0), "")) -> 250005
D25: JL SEDAP MALAM
A26: 13 | B26: 2603078723 | C26: S 4984 OCU | D26: SIGIT PANCORO | E26: DS PULOREJO | F26: NGORO | G26: 417500 | H26: 46091 | J26: =IF(E26="", "", IFERROR(VLOOKUP(IFERROR(VLOOKUP(SUBSTITUTE(E26,"DS ","")&F26, wilayahfix!$A:$D, 2, 0), ""), user!$B:$D, 2, 0), "TIDAK KETEMU")) -> 120281219860120113003 | K26: =IF(E26="", "", IFERROR(VLOOKUP(IFERROR(VLOOKUP(SUBSTITUTE(E26,"DS ","")&F26, wilayahfix!$A:$D, 2, 0), ""), user!$B:$D, 3, 0), "")) -> 250005
D27: DSN. PULOREJO
J28: =IF(E28="", "", IFERROR(VLOOKUP(IFERROR(VLOOKUP(SUBSTITUTE(E28,"DS ","")&F28, wilayahfix!$A:$D, 2, 0), ""), user!$B:$D, 2, 0), "TIDAK KETEMU")) | K28: =IF(E28="", "", IFERROR(VLOOKUP(IFERROR(VLOOKUP(SUBSTITUTE(E28,"DS ","")&F28, wilayahfix!$A:$D, 2, 0), ""), user!$B:$D, 3, 0), ""))
J30: =IF(E30="", "", IFERROR(VLOOKUP(IFERROR(VLOOKUP(SUBSTITUTE(E30,"DS ","")&F30, wilayahfix!$A:$D, 2, 0), ""), user!$B:$D, 2, 0), "TIDAK KETEMU")) | K30: =IF(E30="", "", IFERROR(VLOOKUP(IFERROR(VLOOKUP(SUBSTITUTE(E30,"DS ","")&F30, wilayahfix!$A:$D, 2, 0), ""), user!$B:$D, 3, 0), ""))
J32: =IF(E32="", "", IFERROR(VLOOKUP(IFERROR(VLOOKUP(SUBSTITUTE(E32,"DS ","")&F32, wilayahfix!$A:$D, 2, 0), ""), user!$B:$D, 2, 0), "TIDAK KETEMU")) | K32: =IF(E32="", "", IFERROR(VLOOKUP(IFERROR(VLOOKUP(SUBSTITUTE(E32,"DS ","")&F32, wilayahfix!$A:$D, 2, 0), ""), user!$B:$D, 3, 0), ""))
J34: =IF(E34="", "", IFERROR(VLOOKUP(IFERROR(VLOOKUP(SUBSTITUTE(E34,"DS ","")&F34, wilayahfix!$A:$D, 2, 0), ""), user!$B:$D, 2, 0), "TIDAK KETEMU")) | K34: =IF(E34="", "", IFERROR(VLOOKUP(IFERROR(VLOOKUP(SUBSTITUTE(E34,"DS ","")&F34, wilayahfix!$A:$D, 2, 0), ""), user!$B:$D, 3, 0), ""))
J36: =IF(E36="", "", IFERROR(VLOOKUP(IFERROR(VLOOKUP(SUBSTITUTE(E36,"DS ","")&F36, wilayahfix!$A:$D, 2, 0), ""), user!$B:$D, 2, 0), "TIDAK KETEMU")) | K36: =IF(E36="", "", IFERROR(VLOOKUP(IFERROR(VLOOKUP(SUBSTITUTE(E36,"DS ","")&F36, wilayahfix!$A:$D, 2, 0), ""), user!$B:$D, 3, 0), ""))
J38: =IF(E38="", "", IFERROR(VLOOKUP(IFERROR(VLOOKUP(SUBSTITUTE(E38,"DS ","")&F38, wilayahfix!$A:$D, 2, 0), ""), user!$B:$D, 2, 0), "TIDAK KETEMU")) | K38: =IF(E38="", "", IFERROR(VLOOKUP(IFERROR(VLOOKUP(SUBSTITUTE(E38,"DS ","")&F38, wilayahfix!$A:$D, 2, 0), ""), user!$B:$D, 3, 0), ""))
J40: =IF(E40="", "", IFERROR(VLOOKUP(IFERROR(VLOOKUP(SUBSTITUTE(E40,"DS ","")&F40, wilayahfix!$A:$D, 2, 0), ""), user!$B:$D, 2, 0), "TIDAK KETEMU")) | K40: =IF(E40="", "", IFERROR(VLOOKUP(IFERROR(VLOOKUP(SUBSTITUTE(E40,"DS ","")&F40, wilayahfix!$A:$D, 2, 0), ""), user!$B:$D, 3, 0), ""))
J42: =IF(E42="", "", IFERROR(VLOOKUP(IFERROR(VLOOKUP(SUBSTITUTE(E42,"DS ","")&F42, wilayahfix!$A:$D, 2, 0), ""), user!$B:$D, 2, 0), "TIDAK KETEMU")) | K42: =IF(E42="", "", IFERROR(VLOOKUP(IFERROR(VLOOKUP(SUBSTITUTE(E42,"DS ","")&F42, wilayahfix!$A:$D, 2, 0), ""), user!$B:$D, 3, 0), ""))
J44: =IF(E44="", "", IFERROR(VLOOKUP(IFERROR(VLOOKUP(SUBSTITUTE(E44,"DS ","")&F44, wilayahfix!$A:$D, 2, 0), ""), user!$B:$D, 2, 0), "TIDAK KETEMU")) | K44: =IF(E44="", "", IFERROR(VLOOKUP(IFERROR(VLOOKUP(SUBSTITUTE(E44,"DS ","")&F44, wilayahfix!$A:$D, 2, 0), ""), user!$B:$D, 3, 0), ""))
J46: =IF(E46="", "", IFERROR(VLOOKUP(IFERROR(VLOOKUP(SUBSTITUTE(E46,"DS ","")&F46, wilayahfix!$A:$D, 2, 0), ""), user!$B:$D, 2, 0), "TIDAK KETEMU")) | K46: =IF(E46="", "", IFERROR(VLOOKUP(IFERROR(VLOOKUP(SUBSTITUTE(E46,"DS ","")&F46, wilayahfix!$A:$D, 2, 0), ""), user!$B:$D, 3, 0), ""))
J48: =IF(E48="", "", IFERROR(VLOOKUP(IFERROR(VLOOKUP(SUBSTITUTE(E48,"DS ","")&F48, wilayahfix!$A:$D, 2, 0), ""), user!$B:$D, 2, 0), "TIDAK KETEMU")) | K48: =IF(E48="", "", IFERROR(VLOOKUP(IFERROR(VLOOKUP(SUBSTITUTE(E48,"DS ","")&F48, wilayahfix!$A:$D, 2, 0), ""), user!$B:$D, 3, 0), ""))
J50: =IF(E50="", "", IFERROR(VLOOKUP(IFERROR(VLOOKUP(SUBSTITUTE(E50,"DS ","")&F50, wilayahfix!$A:$D, 2, 0), ""), user!$B:$D, 2, 0), "TIDAK KETEMU")) | K50: =IF(E50="", "", IFERROR(VLOOKUP(IFERROR(VLOOKUP(SUBSTITUTE(E50,"DS ","")&F50, wilayahfix!$A:$D, 2, 0), ""), user!$B:$D, 3, 0), ""))
... J198: =IF(E198="", "", IFERROR(VLOOKUP(IFERROR(VLOOKUP(SUBSTITUTE(E198,"DS ","")&F198, wilayahfix!$A:$D, 2, 0), ""), user!$B:$D, 2, 0), "TIDAK KETEMU")) | K198: =IF(E198="", "", IFERROR(VLOOKUP(IFERROR(VLOOKUP(SUBSTITUTE(E198,"DS ","")&F198, wilayahfix!$A:$D, 2, 0), ""), user!$B:$D, 3, 0), ""))
...

Sheet NTP
A1: NO | B1: NO ENTRI | C1: NOPOL | D1: NAMA / ALAMAT | E1: DESA | F1: KECAMATAN | G1: POTENSI | H1: TGCETAK | I1: KET | J1: ID_Login | K1: Password
A2: 1 | B2: 2603076537 | C2: S 4629 OBU | D2: WESTI ERLIFIANINGRUM | E2: DS BRAMBANG | F2: DIWEK | G2: 243200 | H2: 46091 | J2: =IF(E2="", "", IFERROR(VLOOKUP(IFERROR(VLOOKUP(SUBSTITUTE(E2,"DS ","")&F2, wilayahfix!$A:$D, 2, 0), ""), user!$B:$D, 2, 0), "TIDAK KETEMU")) -> 120201219820720072991 | K2: =IF(E2="", "", IFERROR(VLOOKUP(IFERROR(VLOOKUP(SUBSTITUTE(E2,"DS ","")&F2, wilayahfix!$A:$D, 2, 0), ""), user!$B:$D, 3, 0), "")) -> KADIR
D3: DSN LEGARANG
A4: 2 | B4: 2603064038 | C4: S 3989 ON | D4: DENI ANDRIANTO | E4: DS KAYANGAN | F4: DIWEK | G4: 209200 | H4: 46091 | J4: =IF(E4="", "", IFERROR(VLOOKUP(IFERROR(VLOOKUP(SUBSTITUTE(E4,"DS ","")&F4, wilayahfix!$A:$D, 2, 0), ""), user!$B:$D, 2, 0), "TIDAK KETEMU")) -> 120201219820720072991 | K4: =IF(E4="", "", IFERROR(VLOOKUP(IFERROR(VLOOKUP(SUBSTITUTE(E4,"DS ","")&F4, wilayahfix!$A:$D, 2, 0), ""), user!$B:$D, 3, 0), "")) -> KADIR
D5: DSN TEBON
A6: 3 | B6: 2603071699 | C6: S 2636 OBF | D6: SUYATI | E6: DS NGUDIREJO | F6: DIWEK | G6: 151900 | H6: 46091 | J6: =IF(E6="", "", IFERROR(VLOOKUP(IFERROR(VLOOKUP(SUBSTITUTE(E6,"DS ","")&F6, wilayahfix!$A:$D, 2, 0), ""), user!$B:$D, 2, 0), "TIDAK KETEMU")) -> 120291019860720072992 | K6: =IF(E6="", "", IFERROR(VLOOKUP(IFERROR(VLOOKUP(SUBSTITUTE(E6,"DS ","")&F6, wilayahfix!$A:$D, 2, 0), ""), user!$B:$D, 3, 0), "")) -> SIAPP
D7: DSN GEDANGAN
A8: 4 | B8: 2603099049 | C8: S 2422 OBF | D8: ARYO PUTRO | E8: DS BUGASUR KDLMN | F8: GUDO | G8: 181800 | H8: 46091 | J8: =IF(E8="", "", IFERROR(VLOOKUP(IFERROR(VLOOKUP(SUBSTITUTE(E8,"DS ","")&F8, wilayahfix!$A:$D, 2, 0), ""), user!$B:$D, 2, 0), "TIDAK KETEMU")) -> 198311252010011005 | K8: =IF(E8="", "", IFERROR(VLOOKUP(IFERROR(VLOOKUP(SUBSTITUTE(E8,"DS ","")&F8, wilayahfix!$A:$D, 2, 0), ""), user!$B:$D, 3, 0), "")) -> YAFET
D9: DUSUN SUMBERMIRI
A10: 5 | B10: 2603082823 | C10: S 6944 OAL | D10: IMROATUL FARIDA | E10: DS TANGGUNGAN | F10: GUDO | G10: 196800 | H10: 46091 | J10: =IF(E10="", "", IFERROR(VLOOKUP(IFERROR(VLOOKUP(SUBSTITUTE(E10,"DS ","")&F10, wilayahfix!$A:$D, 2, 0), ""), user!$B:$D, 2, 0), "TIDAK KETEMU")) -> 198311252010011005 | K10: =IF(E10="", "", IFERROR(VLOOKUP(IFERROR(VLOOKUP(SUBSTITUTE(E10,"DS ","")&F10, wilayahfix!$A:$D, 2, 0), ""), user!$B:$D, 3, 0), "")) -> YAFET
D11: DS TANGGUNGAN RW 02/06
A12: 6 | B12: 2603096239 | C12: S 4998 OCU | D12: MUHAMMAD FAQIN RIZAL AZZALI | E12: DS BADANG | F12: NGORO | G12: 267300 | H12: 46091 | J12: =IF(E12="", "", IFERROR(VLOOKUP(IFERROR(VLOOKUP(SUBSTITUTE(E12,"DS ","")&F12, wilayahfix!$A:$D, 2, 0), ""), user!$B:$D, 2, 0), "TIDAK KETEMU")) -> 120281219860120113003 | K12: =IF(E12="", "", IFERROR(VLOOKUP(IFERROR(VLOOKUP(SUBSTITUTE(E12,"DS ","")&F12, wilayahfix!$A:$D, 2, 0), ""), user!$B:$D, 3, 0), "")) -> 250005
D13: DSN SUKOTI
A14: 7 | B14: 2603076608 | C14: S 3922 OAJ | D14: UNTUNG | E14: DS BADANG | F14: NGORO | G14: 196800 | H14: 46091 | J14: =IF(E14="", "", IFERROR(VLOOKUP(IFERROR(VLOOKUP(SUBSTITUTE(E14,"DS ","")&F14, wilayahfix!$A:$D, 2, 0), ""), user!$B:$D, 2, 0), "TIDAK KETEMU")) -> 120281219860120113003 | K14: =IF(E14="", "", IFERROR(VLOOKUP(IFERROR(VLOOKUP(SUBSTITUTE(E14,"DS ","")&F14, wilayahfix!$A:$D, 2, 0), ""), user!$B:$D, 3, 0), "")) -> 250005
D15: WONOASRI
A16: 8 | B16: 2603075042 | C16: S 2362 OBF | D16: FEBRIANA DWI EVAYANTI | E16: DS KAUMAN | F16: NGORO | G16: 270600 | H16: 46091 | J16: =IF(E16="", "", IFERROR(VLOOKUP(IFERROR(VLOOKUP(SUBSTITUTE(E16,"DS ","")&F16, wilayahfix!$A:$D, 2, 0), ""), user!$B:$D, 2, 0), "TIDAK KETEMU")) -> 120281219860120113003 | K16: =IF(E16="", "", IFERROR(VLOOKUP(IFERROR(VLOOKUP(SUBSTITUTE(E16,"DS ","")&F16, wilayahfix!$A:$D, 2, 0), ""), user!$B:$D, 3, 0), "")) -> 250005
D17: DSN KAUMAN
A18: 9 | B18: 2603083988 | C18: S 3983 ON | D18: FARIDA FITRIANA | E18: DS KAUMAN | F18: NGORO | G18: 216700 | H18: 46091 | J18: =IF(E18="", "", IFERROR(VLOOKUP(IFERROR(VLOOKUP(SUBSTITUTE(E18,"DS ","")&F18, wilayahfix!$A:$D, 2, 0), ""), user!$B:$D, 2, 0), "TIDAK KETEMU")) -> 120281219860120113003 | K18: =IF(E18="", "", IFERROR(VLOOKUP(IFERROR(VLOOKUP(SUBSTITUTE(E18,"DS ","")&F18, wilayahfix!$A:$D, 2, 0), ""), user!$B:$D, 3, 0), "")) -> 250005
D19: DSN KRENGGAN
A20: 10 | B20: 2603028068 | C20: S 6901 OCH | D20: ALIEFFIAN SETYO R | E20: DS NGORO | F20: NGORO | G20: 198400 | H20: 46091 | J20: =IF(E20="", "", IFERROR(VLOOKUP(IFERROR(VLOOKUP(SUBSTITUTE(E20,"DS ","")&F20, wilayahfix!$A:$D, 2, 0), ""), user!$B:$D, 2, 0), "TIDAK KETEMU")) -> 120281219860120113003 | K20: =IF(E20="", "", IFERROR(VLOOKUP(IFERROR(VLOOKUP(SUBSTITUTE(E20,"DS ","")&F20, wilayahfix!$A:$D, 2, 0), ""), user!$B:$D, 3, 0), "")) -> 250005
D21: JL SALAK 4
A22: 11 | B22: 2603012223 | C22: S 3972 ON | D22: NURLAILI | E22: DS NGORO | F22: NGORO | G22: 198400 | H22: 46091 | J22: =IF(E22="", "", IFERROR(VLOOKUP(IFERROR(VLOOKUP(SUBSTITUTE(E22,"DS ","")&F22, wilayahfix!$A:$D, 2, 0), ""), user!$B:$D, 2, 0), "TIDAK KETEMU")) -> 120281219860120113003 | K22: =IF(E22="", "", IFERROR(VLOOKUP(IFERROR(VLOOKUP(SUBSTITUTE(E22,"DS ","")&F22, wilayahfix!$A:$D, 2, 0), ""), user!$B:$D, 3, 0), "")) -> 250005
D23: JL SALAK
A24: 12 | B24: 2603087991 | C24: S 4670 OBU | D24: SRI WAHYUNI | E24: DS NGORO | F24: NGORO | G24: 183500 | H24: 46091 | J24: =IF(E24="", "", IFERROR(VLOOKUP(IFERROR(VLOOKUP(SUBSTITUTE(E24,"DS ","")&F24, wilayahfix!$A:$D, 2, 0), ""), user!$B:$D, 2, 0), "TIDAK KETEMU")) -> 120281219860120113003 | K24: =IF(E24="", "", IFERROR(VLOOKUP(IFERROR(VLOOKUP(SUBSTITUTE(E24,"DS ","")&F24, wilayahfix!$A:$D, 2, 0), ""), user!$B:$D, 3, 0), "")) -> 250005
D25: JL SEDAP MALAM
A26: 13 | B26: 2603078723 | C26: S 4984 OCU | D26: SIGIT PANCORO | E26: DS PULOREJO | F26: NGORO | G26: 417500 | H26: 46091 | J26: =IF(E26="", "", IFERROR(VLOOKUP(IFERROR(VLOOKUP(SUBSTITUTE(E26,"DS ","")&F26, wilayahfix!$A:$D, 2, 0), ""), user!$B:$D, 2, 0), "TIDAK KETEMU")) -> 120281219860120113003 | K26: =IF(E26="", "", IFERROR(VLOOKUP(IFERROR(VLOOKUP(SUBSTITUTE(E26,"DS ","")&F26, wilayahfix!$A:$D, 2, 0), ""), user!$B:$D, 3, 0), "")) -> 250005
D27: DSN. PULOREJO
J28: =IF(E28="", "", IFERROR(VLOOKUP(IFERROR(VLOOKUP(SUBSTITUTE(E28,"DS ","")&F28, wilayahfix!$A:$D, 2, 0), ""), user!$B:$D, 2, 0), "TIDAK KETEMU")) | K28: =IF(E28="", "", IFERROR(VLOOKUP(IFERROR(VLOOKUP(SUBSTITUTE(E28,"DS ","")&F28, wilayahfix!$A:$D, 2, 0), ""), user!$B:$D, 3, 0), ""))
J30: =IF(E30="", "", IFERROR(VLOOKUP(IFERROR(VLOOKUP(SUBSTITUTE(E30,"DS ","")&F30, wilayahfix!$A:$D, 2, 0), ""), user!$B:$D, 2, 0), "TIDAK KETEMU")) | K30: =IF(E30="", "", IFERROR(VLOOKUP(IFERROR(VLOOKUP(SUBSTITUTE(E30,"DS ","")&F30, wilayahfix!$A:$D, 2, 0), ""), user!$B:$D, 3, 0), ""))
J32: =IF(E32="", "", IFERROR(VLOOKUP(IFERROR(VLOOKUP(SUBSTITUTE(E32,"DS ","")&F32, wilayahfix!$A:$D, 2, 0), ""), user!$B:$D, 2, 0), "TIDAK KETEMU")) | K32: =IF(E32="", "", IFERROR(VLOOKUP(IFERROR(VLOOKUP(SUBSTITUTE(E32,"DS ","")&F32, wilayahfix!$A:$D, 2, 0), ""), user!$B:$D, 3, 0), ""))
J34: =IF(E34="", "", IFERROR(VLOOKUP(IFERROR(VLOOKUP(SUBSTITUTE(E34,"DS ","")&F34, wilayahfix!$A:$D, 2, 0), ""), user!$B:$D, 2, 0), "TIDAK KETEMU")) | K34: =IF(E34="", "", IFERROR(VLOOKUP(IFERROR(VLOOKUP(SUBSTITUTE(E34,"DS ","")&F34, wilayahfix!$A:$D, 2, 0), ""), user!$B:$D, 3, 0), ""))
J36: =IF(E36="", "", IFERROR(VLOOKUP(IFERROR(VLOOKUP(SUBSTITUTE(E36,"DS ","")&F36, wilayahfix!$A:$D, 2, 0), ""), user!$B:$D, 2, 0), "TIDAK KETEMU")) | K36: =IF(E36="", "", IFERROR(VLOOKUP(IFERROR(VLOOKUP(SUBSTITUTE(E36,"DS ","")&F36, wilayahfix!$A:$D, 2, 0), ""), user!$B:$D, 3, 0), ""))
J38: =IF(E38="", "", IFERROR(VLOOKUP(IFERROR(VLOOKUP(SUBSTITUTE(E38,"DS ","")&F38, wilayahfix!$A:$D, 2, 0), ""), user!$B:$D, 2, 0), "TIDAK KETEMU")) | K38: =IF(E38="", "", IFERROR(VLOOKUP(IFERROR(VLOOKUP(SUBSTITUTE(E38,"DS ","")&F38, wilayahfix!$A:$D, 2, 0), ""), user!$B:$D, 3, 0), ""))
J40: =IF(E40="", "", IFERROR(VLOOKUP(IFERROR(VLOOKUP(SUBSTITUTE(E40,"DS ","")&F40, wilayahfix!$A:$D, 2, 0), ""), user!$B:$D, 2, 0), "TIDAK KETEMU")) | K40: =IF(E40="", "", IFERROR(VLOOKUP(IFERROR(VLOOKUP(SUBSTITUTE(E40,"DS ","")&F40, wilayahfix!$A:$D, 2, 0), ""), user!$B:$D, 3, 0), ""))
J42: =IF(E42="", "", IFERROR(VLOOKUP(IFERROR(VLOOKUP(SUBSTITUTE(E42,"DS ","")&F42, wilayahfix!$A:$D, 2, 0), ""), user!$B:$D, 2, 0), "TIDAK KETEMU")) | K42: =IF(E42="", "", IFERROR(VLOOKUP(IFERROR(VLOOKUP(SUBSTITUTE(E42,"DS ","")&F42, wilayahfix!$A:$D, 2, 0), ""), user!$B:$D, 3, 0), ""))
J44: =IF(E44="", "", IFERROR(VLOOKUP(IFERROR(VLOOKUP(SUBSTITUTE(E44,"DS ","")&F44, wilayahfix!$A:$D, 2, 0), ""), user!$B:$D, 2, 0), "TIDAK KETEMU")) | K44: =IF(E44="", "", IFERROR(VLOOKUP(IFERROR(VLOOKUP(SUBSTITUTE(E44,"DS ","")&F44, wilayahfix!$A:$D, 2, 0), ""), user!$B:$D, 3, 0), ""))
J46: =IF(E46="", "", IFERROR(VLOOKUP(IFERROR(VLOOKUP(SUBSTITUTE(E46,"DS ","")&F46, wilayahfix!$A:$D, 2, 0), ""), user!$B:$D, 2, 0), "TIDAK KETEMU")) | K46: =IF(E46="", "", IFERROR(VLOOKUP(IFERROR(VLOOKUP(SUBSTITUTE(E46,"DS ","")&F46, wilayahfix!$A:$D, 2, 0), ""), user!$B:$D, 3, 0), ""))
J48: =IF(E48="", "", IFERROR(VLOOKUP(IFERROR(VLOOKUP(SUBSTITUTE(E48,"DS ","")&F48, wilayahfix!$A:$D, 2, 0), ""), user!$B:$D, 2, 0), "TIDAK KETEMU")) | K48: =IF(E48="", "", IFERROR(VLOOKUP(IFERROR(VLOOKUP(SUBSTITUTE(E48,"DS ","")&F48, wilayahfix!$A:$D, 2, 0), ""), user!$B:$D, 3, 0), ""))
J50: =IF(E50="", "", IFERROR(VLOOKUP(IFERROR(VLOOKUP(SUBSTITUTE(E50,"DS ","")&F50, wilayahfix!$A:$D, 2, 0), ""), user!$B:$D, 2, 0), "TIDAK KETEMU")) | K50: =IF(E50="", "", IFERROR(VLOOKUP(IFERROR(VLOOKUP(SUBSTITUTE(E50,"DS ","")&F50, wilayahfix!$A:$D, 2, 0), ""), user!$B:$D, 3, 0), ""))
... J198: =IF(E198="", "", IFERROR(VLOOKUP(IFERROR(VLOOKUP(SUBSTITUTE(E198,"DS ","")&F198, wilayahfix!$A:$D, 2, 0), ""), user!$B:$D, 2, 0), "TIDAK KETEMU")) | K198: =IF(E198="", "", IFERROR(VLOOKUP(IFERROR(VLOOKUP(SUBSTITUTE(E198,"DS ","")&F198, wilayahfix!$A:$D, 2, 0), ""), user!$B:$D, 3, 0), ""))
...

Sheet user
A1: No | B1: Nama | C1: Id_Login | D1: Password
A2: 1 | B2: SOESENO | C2: 196904231998031004 | D2: SENO
A3: 2 | B3: ARINI PRIBADI | C3: 198304162011012004 | D3: ARN16
A4: 3 | B4: KURNIAWAN PRATAMA | C4: 198601112011011006 | D4: KURNIAWAN
A5: 4 | B5: TOTOK HADI WINASTO | C5: 197001172008011009 | D5: ADMIN
A6: 5 | B6: M KUKUH CAHYANTO | C6: 197301302007011007 | D6: KUKUH
A7: 6 | B7: IMAM SUJARWO | C7: 197608082010011008 | D7: JRW
A8: 7 | B8: SOEKARI AGUNG SANJOTO | C8: 19711203200811005 | D8: AGUNG
A9: 8 | B9: ARSYIDA RISHANG SIFANI | C9: 200004242022022001 | D9: ARS
A10: 9 | B10: NURDIANTO INDRA | C10: 198411182023211015 | D10: INDRA
A11: 10 | B11: AHMAD KADIR | C11: 120201219820720072991 | D11: KADIR
A12: 11 | B12: ANJAS SASMITA | C12: 120291019860720072992 | D12: SIAPP
A13: 12 | B13: SISWANTO | C13: 120241219780720073002 | D13: SIS
... A18: 17 | B18: EKO SUSANTO | C18: 120050619790220112980 | D18: GRESIK
A19: 18 | B19: WAWAN UTOMO | C19: 120281219860120113003 | D19: 250005
A20: 19 | B20: DAVID SASONGKO | C20: 120011119910120112993 | D20: MASSDAFF17
A21: 20 | B21: ARDIANSYAH M | C21: 120090419830220113123 | D21: ARDN251
A22: 21 | B22: DESSY AMANDAH NURMATIK | C22: 120301219900120132994 | D22: DESI
A23: 22 | B23: SAMSUL ARIF | C23: 120260319850320153114 | D23: SAM461
A24: 23 | B24: RINALDI DWI SAYOGA S.Kom | C24: 199303072025041008 | D24: YOGA
A25: 24 | B25: MOCHAMAD BACHTIAR SETYO H S.Kom | C25: 199805292025041008 | D25: BACHTIAR
A26: 25 | B26: PANGESTI INDAH PUSPITASARI S.Tr.Stat | C26: 199909162025042006 | D26: HESTI
A27: 26 | B27: EKA NURRIZEKI AMALIYA SE | C27: 199707082025042010 | D27: EKANUR
A28: 27 | B28: ARIMA SURYANI S.Kom | C28: 200203232025042003 | D28: ARIMA
A29: 28 | B29: RISA | C29: 199008212024212001 | D29: STRONG
A30: 29 | B30: KARYONO | C30: 196808181994031009 | D30: KARYONO
A31: 30 | B31: JOJOK RACHMAT WIBOWO | C31: 196901041994031005 | D31: WIBOWO
A32: 31 | B32: YAFET DARWANTO | C32: 198311252010011005 | D32: YAFET

Sheet wilayahfix
B1: NAMA | C1: WILAYAH | D1: DESA
A2: =D2&C2 -> BANDARKEDUNGMULYOBANDAR KEDUNG MULYO | B2: SOEKARI AGUNG SANJOTO | C2: BANDAR KEDUNG MULYO | D2: BANDARKEDUNGMULYO
A3: =D3&C3 -> BANJARSARIBANDAR KEDUNG MULYO | B3: SOEKARI AGUNG SANJOTO | C3: BANDAR KEDUNG MULYO | D3: BANJARSARI
A4: =D4&C4 -> BARONGSAWAHANBANDAR KEDUNG MULYO | B4: SOEKARI AGUNG SANJOTO | C4: BANDAR KEDUNG MULYO | D4: BARONGSAWAHAN
A5: =D5&C5 -> BRANGKALBANDAR KEDUNG MULYO | B5: SOEKARI AGUNG SANJOTO | C5: BANDAR KEDUNG MULYO | D5: BRANGKAL
A6: =D6&C6 -> BRODOTBANDAR KEDUNG MULYO | B6: SOEKARI AGUNG SANJOTO | C6: BANDAR KEDUNG MULYO | D6: BRODOT
A7: =D7&C7 -> GONDANGMANISBANDAR KEDUNG MULYO | B7: SOEKARI AGUNG SANJOTO | C7: BANDAR KEDUNG MULYO | D7: GONDANGMANIS
A8: =D8&C8 -> KARANGDAGANGANBANDAR KEDUNG MULYO | B8: SOEKARI AGUNG SANJOTO | C8: BANDAR KEDUNG MULYO | D8: KARANGDAGANGAN
A9: =D9&C9 -> KAYENBANDAR KEDUNG MULYO | B9: SOEKARI AGUNG SANJOTO | C9: BANDAR KEDUNG MULYO | D9: KAYEN
A10: =D10&C10 -> MOJOKAMBANGBANDAR KEDUNG MULYO | B10: SOEKARI AGUNG SANJOTO | C10: BANDAR KEDUNG MULYO | D10: MOJOKAMBANG
A11: =D11&C11 -> PUCANGSIMOBANDAR KEDUNG MULYO | B11: SOEKARI AGUNG SANJOTO | C11: BANDAR KEDUNG MULYO | D11: PUCANGSIMO
A12: =D12&C12 -> TINGGARBANDAR KEDUNG MULYO | B12: SOEKARI AGUNG SANJOTO | C12: BANDAR KEDUNG MULYO | D12: TINGGAR
A13: =D13&C13 -> GADINGMANGUPERAK | B13: ARINI PRIBADI | C13: PERAK | D13: GADINGMANGU
... A307: =D307&C307 -> GROBOGANMOJOWARNO | B307: YAFET DARWANTO | C307: MOJOWARNO | D307: GROBOGAN
